Workbook

Sheet Giocatori
A1: venduto | B1: nome | C1: soprannome | D1: nome_completo | E1: ruolo | F1: squadra | G1: eta | H1: titolare | I1: da_titolare | J1: pct_titolare | K1: presenze | L1: gol | M1: assist | N1: presenze_prev | O1: gol_prev | P1: assist_prev | Q1: titolare_fonte | R1: obiettivo | S1: fascia | T1: prezzo_indicativo | U1: punteggio | V1: fm | W1: mv | X1: rig_segnati | Y1: fm_prev | Z1: mv_prev | AA1: rig_segnati_prev | AB1: delta_fm | AC1: fm_ponderata | AD1: bonus | AE1: squadra_prev | AF1: cambiato_squadra | AG1: rigorista | AH1: piazzati | AI1: indisponibile | AJ1: infortunio | AK1: rientro_data | AL1: giorni_stop | AM1: stop_lungo | AN1: rientro_nota | AO1: gs_partita_squadra | AP1: gs_partita_squadra_prev | AQ1: rig_parati_prev | AR1: ammonizioni_prev | AS1: espulsioni_prev | AT1: id
B2: Bijlow | E2: P | F2: Genoa | G2: 28 | H2: 1 | I2: 4 | J2: 1 | K2: 4 | L2: 0 | M2: 0 | N2: 16 | O2: 0 | P2: 0 | Q2: probabili formazioni | S2: Scommessa | T2: 1-3 | U2: 5.5 | V2: 4.12 | W2: 6.12 | X2: 0 | Y2: 5.31 | Z2: 6.28 | AA2: 0 | AB2: -1.19 | AC2: 4.8 | AD2: 0.7 | AE2: Genoa | AF2: 0 | AG2: 0 | AH2: 0 | AO2: 2 | AP2: 1.34 | AQ2: 0 | AR2: 1 | AS2: 0 | AT2: 59898
B3: Butez | E3: P | F3: Como | G3: 31 | H3: 1 | I3: 3 | J3: 0.75 | K3: 3 | L3: 0 | M3: 0 | N3: 38 | O3: 0 | P3: 1 | Q3: stima da presenze | S3: Medio | T3: 4-11 | U3: 6.57 | V3: 5.33 | W3: 6.33 | X3: 0 | Y3: 6.24 | Z3: 6.45 | AA3: 0 | AB3: -0.91 | AC3: 6.07 | AD3: 0.5 | AE3: Como 1907 | AF3: 0 | AG3: 0 | AH3: 0 | AO3: 1 | AP3: 0.76 | AQ3: 0 | AR3: 3 | AS3: 0 | AT3: 98983
B4: Caprile | E4: P | F4: Cagliari | G4: 25 | H4: 1 | I4: 4 | J4: 1 | K4: 4 | L4: 0 | M4: 0 | N4: 38 | O4: 0 | P4: 0 | Q4: probabili formazioni | S4: Scommessa | T4: 1-3 | U4: 6.12 | V4: 6.75 | W4: 6.75 | X4: 0 | Y4: 5 | Z4: 6.21 | AA4: 0 | AB4: 1.75 | AC4: 5.42 | AD4: 0.7 | AE4: Cagliari | AF4: 0 | AG4: 0 | AH4: 0 | AO4: 0.5 | AP4: 1.39 | AQ4: 0 | AR4: 2 | AS4: 0 | AT4: 69665
B5: Carnesecchi | E5: P | F5: Atalanta | G5: 26 | H5: 1 | I5: 4 | J5: 1 | K5: 4 | L5: 0 | M5: 0 | N5: 37 | O5: 0 | P5: 0 | Q5: probabili formazioni | S5: Medio | T5: 4-11 | U5: 6.59 | V5: 5.75 | W5: 6.75 | X5: 0 | Y5: 5.93 | Z5: 6.36 | AA5: 0 | AB5: -0.18 | AC5: 5.89 | AD5: 0.7 | AE5: Atalanta | AF5: 0 | AG5: 0 | AH5: 0 | AO5: 1.25 | AP5: 0.95 | AQ5: 0 | AR5: 0 | AS5: 0 | AT5: 70334
B6: Corvi | E6: P | F6: Parma | G6: 25 | H6: 1 | I6: 4 | J6: 1 | K6: 4 | L6: 0 | M6: 0 | N6: 17 | O6: 0 | P6: 0 | Q6: probabili formazioni | S6: Scommessa | T6: 1-3 | U6: 5.95 | V6: 4.62 | W6: 6.12 | X6: 0 | Y6: 5.69 | Z6: 6.28 | AA6: 0 | AB6: -1.07 | AC6: 5.25 | AD6: 0.7 | AE6: Parma | AF6: 0 | AG6: 0 | AH6: 0 | AO6: 1.5 | AP6: 1.21 | AQ6: 0 | AR6: 1 | AS6: 0 | AT6: 73141
B7: David de Gea | E7: P | F7: Fiorentina | G7: 36 | H7: 1 | I7: 4 | J7: 1 | K7: 4 | L7: 0 | M7: 0 | N7: 37 | O7: 0 | P7: 0 | Q7: probabili formazioni | S7: Scommessa | T7: 1-3 | U7: 5.01 | V7: 3.25 | W7: 6 | X7: 0 | Y7: 5.32 | Z7: 6.3 | AA7: 0 | AB7: -2.07 | AC7: 4.81 | AD7: 0.2 | AE7: Fiorentina | AF7: 0 | AG7: 0 | AH7: 0 | AO7: 2.75 | AP7: 1.32 | AQ7: 0 | AR7: 0 | AS7: 0 | AT7: 16631
B8: Falcone | E8: P | F8: Lecce | G8: 31 | H8: 1 | I8: 4 | J8: 1 | K8: 4 | L8: 0 | M8: 0 | N8: 38 | O8: 0 | P8: 0 | Q8: probabili formazioni | S8: Scommessa | T8: 1-3 | U8: 5.67 | V8: 5 | W8: 6.62 | X8: 0 | Y8: 5.22 | Z8: 6.14 | AA8: 0 | AB8: -0.22 | AC8: 5.17 | AD8: 0.5 | AE8: Lecce | AF8: 0 | AG8: 0 | AH8: 0 | AO8: 1.75 | AP8: 1.32 | AQ8: 0 | AR8: 2 | AS8: 0 | AT8: 38409
B9: Josep Martinez | E9: P | F9: Inter | G9: 28 | H9: 1 | I9: 4 | J9: 1 | K9: 4 | L9: 0 | M9: 0 | N9: 5 | O9: 0 | P9: 0 | Q9: probabili formazioni | S9: Medio | T9: 4-11 | U9: 6.34 | V9: 5.38 | W9: 6.62 | X9: 0 | Y9: 6.25 | Z9: 6.42 | AA9: 0 | AB9: -0.87 | AC9: 5.64 | AD9: 0.7 | AE9: Inter | AF9: 0 | AG9: 0 | AH9: 0 | AO9: 1.5 | AP9: 0.92 | AQ9: 0 | AR9: 0 | AS9: 0 | AT9: 95090
B10: Lucas Perri | E10: P | F10: Torino | G10: 29 | H10: 0 | I10: 2 | J10: 0.5 | K10: 2 | L10: 0 | M10: 0 | S10: Scommessa | T10: 1-3 | U10: 4.95 | V10: 4.75 | W10: 6.25 | X10: 0 | AC10: 4.75 | AD10: 0.2 | AF10: 0 | AG10: 0 | AH10: 0 | AO10: 1.75 | AP10: 1.66 | AT10: 118370
B11: Maignan | E11: P | F11: Milan | G11: 31 | H11: 1 | I11: 4 | J11: 1 | K11: 4 | L11: 0 | M11: 0 | N11: 37 | O11: 0 | P11: 0 | Q11: probabili formazioni | S11: Medio | T11: 4-11 | U11: 6.35 | V11: 5.5 | W11: 6.25 | X11: 0 | Y11: 5.96 | Z11: 6.42 | AA11: 0 | AB11: -0.46 | AC11: 5.85 | AD11: 0.5 | AE11: Milan | AF11: 0 | AG11: 0 | AH11: 0 | AO11: 1 | AP11: 0.92 | AQ11: 0 | AR11: 4 | AS11: 0 | AT11: 42646
B12: Mandas | E12: P | F12: Lazio | G12: 25 | H12: 1 | I12: 4 | J12: 1 | K12: 4 | L12: 0 | M12: 0 | Q12: probabili formazioni | S12: Top | T12: 25-45 | U12: 7.2 | V12: 6.5 | W12: 6.75 | X12: 0 | AC12: 6.5 | AD12: 0.7 | AF12: 0 | AG12: 0 | AH12: 0 | AO12: 0.75 | AP12: 1.05 | AT12: 118319
B13: Mascardi | E13: P | F13: Torino | G13: 20 | H13: 0 | I13: 2 | J13: 0.5 | K13: 2 | L13: 0 | M13: 0 | S13: Scommessa | T13: 1-3 | U13: 4.45 | V13: 4.25 | W13: 6.25 | X13: 0 | AC13: 4.25 | AD13: 0.2 | AF13: 0 | AG13: 0 | AH13: 0 | AO13: 1.75 | AP13: 1.66 | AT13: 118649
B14: Meret | E14: P | F14: Napoli | G14: 29 | H14: 0 | I14: 3 | J14: 0.75 | K14: 3 | L14: 0 | M14: 0 | N14: 11 | O14: 0 | P14: 1 | S14: Scommessa | T14: 1-3 | U14: 5.43 | V14: 5 | W14: 6.33 | X14: 0 | Y14: 5.79 | Z14: 6.46 | AA14: 0 | AB14: -0.79 | AC14: 5.43 | AD14: 0 | AE14: Napoli | AF14: 0 | AG14: 0 | AH14: 0 | AI14: infortunato | AJ14: Infortunio agli adduttori | AK14: 08/10/2026 | AL14: 22 | AN14: Il portiere uscito claudicante dal match di mercoledì in Champions League per una lesione di basso grado all'adduttore lungo. Recuperabile dall'inizio di ottobre. | AO14: 1.25 | AP14: 0.95 | AQ14: 0 | AR14: 1 | AS14: 0 | AT14: 49089
B15: Milinkovic-Savic | E15: P | F15: Napoli | G15: 29 | H15: 1 | I15: 1 | J15: 0.25 | K15: 1 | L15: 0 | M15: 0 | N15: 27 | O15: 0 | P15: 1 | Q15: probabili formazioni | S15: Semi-top | T15: 12-24 | U15: 7.1 | V15: 7.5 | W15: 6.5 | X15: 0 | Y15: 6.28 | Z15: 6.41 | AA15: 0 | AB15: 1.22 | AC15: 6.4 | AD15: 0.7 | AE15: Napoli | AF15: 0 | AG15: 0 | AH15: 0 | AO15: 1.25 | AP15: 0.95 | AQ15: 0 | AR15: 0 | AS15: 0 | AT15: 44633
B16: Muric | E16: P | F16: Sassuolo | G16: 28 | H16: 1 | I16: 4 | J16: 1 | K16: 4 | L16: 0 | M16: 0 | N16: 32 | O16: 0 | P16: 0 | Q16: probabili formazioni | S16: Scommessa | T16: 1-3 | U16: 5.77 | V16: 4.75 | W16: 6.5 | X16: 0 | Y16: 5.19 | Z16: 6.31 | AA16: 0 | AB16: -0.44 | AC16: 5.07 | AD16: 0.7 | AE16: Sassuolo | AF16: 0 | AG16: 0 | AH16: 0 | AO16: 1.75 | AP16: 1.32 | AQ16: 0 | AR16: 4 | AS16: 0 | AT16: 94916
B17: Okoye | E17: P | F17: Udinese | G17: 27 | H17: 1 | I17: 4 | J17: 1 | K17: 4 | L17: 0 | M17: 0 | N17: 30 | O17: 0 | P17: 0 | Q17: probabili formazioni | S17: Scommessa | T17: 1-3 | U17: 5.83 | V17: 3.88 | W17: 6.38 | X17: 0 | Y17: 5.63 | Z17: 6.28 | AA17: 0 | AB17: -1.75 | AC17: 5.13 | AD17: 0.7 | AE17: Udinese | AF17: 0 | AG17: 0 | AH17: 0 | AO17: 2.5 | AP17: 1.26 | AQ17: 0 | AR17: 1 | AS17: 1 | AT17: 77144
B18: Palmisani | E18: P | F18: Frosinone | G18: 22 | H18: 1 | I18: 4 | J18: 1 | K18: 4 | L18: 0 | M18: 0 | Q18: probabili formazioni | S18: Scommessa | T18: 1-3 | U18: 6.2 | V18: 5.5 | W18: 6.25 | X18: 0 | AC18: 5.5 | AD18: 0.7 | AF18: 0 | AG18: 0 | AH18: 0 | AO18: 1 | AT18: 110653
B19: Pessina | E19: P | F19: Bologna | G19: 19 | H19: 0 | I19: 1 | J19: 0.25 | K19: 1 | L19: 0 | M19: 0 | N19: 4 | O19: 0 | P19: 0 | S19: Scommessa | T19: 1-3 | U19: 5.93 | V19: 5 | W19: 6 | X19: 0 | Y19: 6.8 | Z19: 6.4 | AA19: 0 | AB19: -1.8 | AC19: 6.03 | AD19: -0.1 | AE19: Bologna | AF19: 0 | AG19: 0 | AH19: 0 | AO19: 1.25 | AP19: 1.21 | AQ19: 0 | AR19: 0 | AS19: 0 | AT19: 119794
B20: Robert Sanchez | E20: P | F20: Como | G20: 29 | H20: 0 | I20: 1 | J20: 0.25 | K20: 1 | L20: 0 | M20: 0 | S20: Scommessa | T20: 1-3 | U20: 5.7 | V20: 5.5 | W20: 6.5 | X20: 0 | AC20: 5.5 | AD20: 0.2 | AF20: 0 | AG20: 0 | AH20: 0 | AO20: 1 | AP20: 0.76 | AT20: 94809
B21: Skorupski | E21: P | F21: Bologna | G21: 35 | H21: 1 | I21: 3 | J21: 0.75 | K21: 3 | L21: 0 | M21: 0 | N21: 19 | O21: 0 | P21: 0 | Q21: probabili formazioni | S21: Scommessa | T21: 1-3 | U21: 5.61 | V21: 4.67 | W21: 6 | X21: 0 | Y21: 5.76 | Z21: 6.16 | AA21: 0 | AB21: -1.09 | AC21: 5.41 | AD21: 0.2 | AE21: Bologna | AF21: 0 | AG21: 0 | AH21: 0 | AO21: 1.25 | AP21: 1.21 | AQ21: 0 | AR21: 1 | AS21: 1 | AT21: 38871
B22: Stankovic | E22: P | F22: Venezia | G22: 24 | H22: 1 | I22: 4 | J22: 1 | K22: 4 | L22: 0 | M22: 0 | Q22: probabili formazioni | S22: Scommessa | T22: 1-3 | U22: 4.2 | V22: 3.5 | W22: 6.25 | X22: 0 | AC22: 3.5 | AD22: 0.7 | AF22: 0 | AG22: 0 | AH22: 0 | AO22: 2.75 | AT22: 102651
B23: Svilar | E23: P | F23: Roma | G23: 27 | H23: 1 | I23: 4 | J23: 1 | K23: 4 | L23: 0 | M23: 0 | N23: 38 | O23: 0 | P23: 0 | Q23: probabili formazioni | S23: Semi-top | T23: 12-24 | U23: 7.06 | V23: 7.12 | W23: 6.62 | X23: 0 | Y23: 6.12 | Z23: 6.46 | AA23: 0 | AB23: 1 | AC23: 6.36 | AD23: 0.7 | AE23: Roma | AF23: 0 | AG23: 0 | AH23: 0 | AO23: 0.25 | AP23: 0.82 | AQ23: 0 | AR23: 0 | AS23: 0 | AT23: 60457
B24: Thiam | E24: P | F24: Monza | G24: 28 | H24: 1 | I24: 3 | J24: 0.75 | K24: 3 | L24: 0 | M24: 0 | Q24: probabili formazioni | S24: Scommessa | T24: 1-3 | U24: 4.2 | V24: 3.5 | W24: 5.83 | X24: 0 | AC24: 3.5 | AD24: 0.7 | AF24: 0 | AG24: 0 | AH24: 0 | AO24: 2.75 | AT24: 61406
B25: Vicario | E25: P | F25: Juventus | G25: 30 | H25: 1 | I25: 4 | J25: 1 | K25: 4 | L25: 0 | M25: 0 | Q25: probabili formazioni | S25: Medio | T25: 4-11 | U25: 6.25 | V25: 5.75 | W25: 6.25 | X25: 0 | AC25: 5.75 | AD25: 0.5 | AF25: 0 | AG25: 0 | AH25: 0 | AO25: 1 | AP25: 0.89 | AT25: 45335
B26: Abankwah | E26: D | F26: Udinese | G26: 22 | H26: 1 | I26: 4 | J26: 1 | K26: 4 | L26: 1 | M26: 0 | Q26: probabili formazioni | S26: Semi-top | T26: 15-29 | U26: 7.58 | V26: 6.88 | W26: 6.25 | X26: 0 | AC26: 6.88 | AD26: 0.7 | AF26: 0 | AG26: 0 | AH26: 0 | AO26: 2.5 | AP26: 1.26 | AT26: 115130
B27: Akanji | E27: D | F27: Inter | G27: 31 | H27: 1 | I27: 4 | J27: 1 | K27: 4 | L27: 0 | M27: 1 | N27: 33 | O27: 2 | P27: 0 | Q27: probabili formazioni | S27: Medio | T27: 5-14 | U27: 6.89 | V27: 6.5 | W27: 6.5 | X27: 0 | Y27: 6.35 | Z27: 6.23 | AA27: 0 | AB27: 0.15 | AC27: 6.39 | AD27: 0.5 | AE27: Inter | AF27: 0 | AG27: 0 | AH27: 0 | AO27: 1.5 | AP27: 0.92 | AQ27: 0 | AR27: 4 | AS27: 0 | AT27: 51611
B28: Alex Jimenez | E28: D | F28: Fiorentina | G28: 21 | H28: 1 | I28: 2 | J28: 0.5 | K28: 3 | L28: 0 | M28: 1 | Q28: probabili formazioni | S28: Medio | T28: 5-14 | U28: 6.87 | V28: 6.17 | W28: 6.17 | X28: 0 | AC28: 6.17 | AD28: 0.7 | AF28: 0 | AG28: 0 | AH28: 0 | AO28: 2.75 | AP28: 1.32 | AT28: 118586
B29: Alex Valle | E29: D | F29: Como | G29: 22 | H29: 1 | I29: 3 | J29: 0.75 | K29: 3 | L29: 0 | M29: 1 | N29: 28 | O29: 1 | P29: 4 | Q29: stima da presenze | R29: obiettivo mercato | S29: Semi-top | T29: 15-29 | U29: 7.14 | V29: 6.83 | W29: 6.67 | X29: 0 | Y29: 6.31 | Z29: 6.19 | AA29: 0 | AB29: 0.52 | AC29: 6.44 | AD29: 0.7 | AE29: Como 1907 | AF29: 0 | AG29: 0 | AH29: 0 | AO29: 1 | AP29: 0.76 | AQ29: 0 | AR29: 3 | AS29: 0 | AT29: 115890
B30: Alfonso Pedraza | E30: D | F30: Lazio | G30: 30 | H30: 0 | I30: 1 | J30: 0.25 | K30: 3 | L30: 0 | M30: 0 | S30: Scommessa | T30: 1-4 | U30: 6 | V30: 6 | W30: 6 | X30: 0 | AC30: 6 | AD30: 0 | AF30: 0 | AG30: 0 | AH30: 0 | AO30: 0.75 | AP30: 1.05 | AT30: 50622
B31: Alhassane | E31: D | F31: Bologna | G31: 24 | H31: 0 | I31: 2 | J31: 0.5 | K31: 2 | L31: 0 | M31: 0 | S31: Scommessa | T31: 1-4 | U31: 5.95 | V31: 5.75 | W31: 5.75 | X31: 0 | AC31: 5.75 | AD31: 0.2 | AF31: 0 | AG31: 0 | AH31: 0 | AO31: 1.25 | AP31: 1.21 | AT31: 120604
B32: Amey | E32: D | F32: Frosinone | G32: 21 | H32: 0 | I32: 0 | J32: 0 | K32: 1 | L32: 0 | M32: 0 | S32: Scommessa | T32: 1-4 | U32: 0.2 | V32: 0 | W32: 0 | X32: 0 | AC32: 0 | AD32: 0.2 | AF32: 0 | AG32: 0 | AH32: 0 | AO32: 1 | AT32: 109534
B33: Arizala | E33: D | F33: Udinese | G33: 21 | H33: 0 | I33: 0 | J33: 0 | K33: 1 | L33: 0 | M33: 0 | N33: 10 | O33: 0 | P33: 0 | S33: Scommessa | T33: 1-4 | U33: 4.08 | V33: 0 | W33: 0 | X33: 0 | Y33: 5.69 | Z33: 5.69 | AA33: 0 | AB33: -5.69 | AC33: 4.38 | AD33: -0.3 | AE33: Udinese | AF33: 0 | AG33: 0 | AH33: 0 | AI33: infortunato | AJ33: Infortunio al bicipite femorale | AK33: 06/10/2026 | AL33: 20 | AN33: il difensore fermo dal 6 settembre vittima di una lesione muscolare al bicipite femorale. Condizioni da valutare, ma dovrebbe tornare convocabile dalla prima metà di ottobre. | AO33: 2.5 | AP33: 1.26 | AQ33: 0 | AR33: 0 | AS33: 0 | AT33: 120272
B34: Aurelio | E34: D | F34: Cagliari | G34: 26 | H34: 0 | I34: 0 | J34: 0 | K34: 1 | L34: 0 | M34: 0 | S34: Scommessa | T34: 1-4 | U34: 0.2 | V34: 0 | W34: 0 | X34: 0 | AC34: 0 | AD34: 0.2 | AF34: 0 | AG34: 0 | AH34: 0 | AO34: 0.5 | AP34: 1.39 | AT34: 95257
B35: Badiashile | E35: D | F35: Napoli | G35: 25 | H35: 0 | I35: 0 | J35: 0 | K35: 1 | L35: 0 | M35: 0 | S35: Scommessa | T35: 1-4 | U35: 5.7 | V35: 5.5 | W35: 5.5 | X35: 0 | AC35: 5.5 | AD35: 0.2 | AF35: 0 | AG35: 0 | AH35: 0 | AO35: 1.25 | AP35: 0.95 | AT35: 69996
B36: Bakoune | E36: D | F36: Monza | G36: 20 | H36: 1 | I36: 1 | J36: 0.25 | K36: 3 | L36: 0 | M36: 0 | Q36: probabili formazioni | S36: Scommessa | T36: 1-4 | U36: 6.45 | V36: 5.75 | W36: 5.75 | X36: 0 | AC36: 5.75 | AD36: 0.7 | AF36: 0 | AG36: 0 | AH36: 0 | AO36: 2.75 | AT36: 120499
B37: Balerdi | E37: D | F37: Roma | G37: 27 | H37: 0 | I37: 1 | J37: 0.25 | K37: 2 | L37: 0 | M37: 0 | S37: Scommessa | T37: 1-4 | U37: 6.45 | V37: 6.25 | W37: 6.25 | X37: 0 | AC37: 6.25 | AD37: 0.2 | AF37: 0 | AG37: 0 | AH37: 0 | AO37: 0.25 | AP37: 0.82 | AT37: 95361
B38: Bartesaghi | E38: D | F38: Milan | G38: 21 | H38: 0 | I38: 1 | J38: 0.25 | K38: 2 | L38: 0 | M38: 0 | N38: 31 | O38: 2 | P38: 0 | S38: Scommessa | T38: 1-4 | U38: 6.53 | V38: 6 | W38: 6 | X38: 0 | Y38: 6.39 | Z38: 6.31 | AA38: 0 | AB38: -0.39 | AC38: 6.33 | AD38: 0.2 | AE38: Milan | AF38: 0 | AG38: 0 | AH38: 0 | AO38: 1 | AP38: 0.92 | AQ38: 0 | AR38: 3 | AS38: 0 | AT38: 118223
B39: Bastoni | E39: D | F39: Inter | G39: 27 | H39: 1 | I39: 4 | J39: 1 | K39: 4 | L39: 0 | M39: 0 | N39: 28 | O39: 1 | P39: 4 | Q39: probabili formazioni | S39: Semi-top | T39: 15-29 | U39: 7.18 | V39: 6.38 | W39: 6.38 | X39: 0 | Y39: 6.52 | Z39: 6.41 | AA39: 0 | AB39: -0.14 | AC39: 6.48 | AD39: 0.7 | AE39: Inter | AF39: 0 | AG39: 0 | AH39: 0 | AO39: 1.5 | AP39: 0.92 | AQ39: 0 | AR39: 6 | AS39: 0 | AT39: 61306
B40: Belghali | E40: D | F40: Torino | G40: 24 | H40: 0 | I40: 1 | J40: 0.25 | K40: 2 | L40: 0 | M40: 1 | N40: 26 | O40: 2 | P40: 0 | S40: Scommessa | T40: 1-4 | U40: 6.15 | V40: 6 | W40: 5.75 | X40: 0 | Y40: 5.94 | Z40: 5.83 | AA40: 0 | AB40: 0.06 | AC40: 5.95 | AD40: 0.2 | AE40: Verona | AF40: 1 | AG40: 0 | AH40: 0 | AO40: 1.75 | AP40: 1.61 | AQ40: 0 | AR40: 6 | AS40: 0 | AT40: 120135
...

Sheet Portieri
A1: venduto | B1: nome | C1: soprannome | D1: squadra | E1: eta | F1: titolare | G1: da_titolare | H1: pct_titolare | I1: presenze | J1: presenze_prev | K1: squadra_prev | L1: gs_partita_squadra_prev | M1: gs_squadra_prev | N1: gs_partita_squadra | O1: gs_squadra | P1: rig_parati_prev | Q1: mv_prev | R1: fm_prev | S1: mv | T1: fm | U1: fascia | V1: prezzo_indicativo | W1: punteggio | X1: indisponibile | Y1: rientro_data | Z1: stop_lungo | AA1: id
A2: =IF($AA2="","",IFERROR(INDEX(Giocatori!$A:$A,MATCH($AA2,Giocatori!$AT:$AT,0)),"")) | B2: Butez | D2: Como | E2: 31 | F2: 1 | G2: 3 | H2: 0.75 | I2: 3 | J2: 38 | K2: Como 1907 | L2: 0.76 | M2: 29 | N2: 1 | O2: 4 | P2: 0 | Q2: 6.45 | R2: 6.24 | S2: 6.33 | T2: 5.33 | U2: Medio | V2: 4-11 | W2: 6.57 | AA2: 98983
A3: =IF($AA3="","",IFERROR(INDEX(Giocatori!$A:$A,MATCH($AA3,Giocatori!$AT:$AT,0)),"")) | B3: Svilar | D3: Roma | E3: 27 | F3: 1 | G3: 4 | H3: 1 | I3: 4 | J3: 38 | K3: Roma | L3: 0.82 | M3: 31 | N3: 0.25 | O3: 1 | P3: 0 | Q3: 6.46 | R3: 6.12 | S3: 6.62 | T3: 7.12 | U3: Semi-top | V3: 12-24 | W3: 7.06 | AA3: 60457
A4: =IF($AA4="","",IFERROR(INDEX(Giocatori!$A:$A,MATCH($AA4,Giocatori!$AT:$AT,0)),"")) | B4: Maignan | D4: Milan | E4: 31 | F4: 1 | G4: 4 | H4: 1 | I4: 4 | J4: 37 | K4: Milan | L4: 0.92 | M4: 35 | N4: 1 | O4: 4 | P4: 0 | Q4: 6.42 | R4: 5.96 | S4: 6.25 | T4: 5.5 | U4: Medio | V4: 4-11 | W4: 6.35 | AA4: 42646
A5: =IF($AA5="","",IFERROR(INDEX(Giocatori!$A:$A,MATCH($AA5,Giocatori!$AT:$AT,0)),"")) | B5: Milinkovic-Savic | D5: Napoli | E5: 29 | F5: 1 | G5: 1 | H5: 0.25 | I5: 1 | J5: 27 | K5: Napoli | L5: 0.95 | M5: 36 | N5: 1.25 | O5: 5 | P5: 0 | Q5: 6.41 | R5: 6.28 | S5: 6.5 | T5: 7.5 | U5: Semi-top | V5: 12-24 | W5: 7.1 | AA5: 44633
A6: =IF($AA6="","",IFERROR(INDEX(Giocatori!$A:$A,MATCH($AA6,Giocatori!$AT:$AT,0)),"")) | B6: Carnesecchi | D6: Atalanta | E6: 26 | F6: 1 | G6: 4 | H6: 1 | I6: 4 | J6: 37 | K6: Atalanta | L6: 0.95 | M6: 36 | N6: 1.25 | O6: 5 | P6: 0 | Q6: 6.36 | R6: 5.93 | S6: 6.75 | T6: 5.75 | U6: Medio | V6: 4-11 | W6: 6.59 | AA6: 70334

Sheet Difensori
A1: venduto | B1: nome | C1: soprannome | D1: squadra | E1: eta | F1: titolare | G1: da_titolare | H1: pct_titolare | I1: presenze | J1: gol | K1: assist | L1: presenze_prev | M1: gol_prev | N1: assist_prev | O1: obiettivo | P1: rigorista | Q1: piazzati | R1: mv | S1: mv_prev | T1: fm | U1: fm_prev | V1: titolare_fonte | W1: fascia | X1: prezzo_indicativo | Y1: punteggio | Z1: indisponibile | AA1: rientro_data | AB1: stop_lungo | AC1: id
A2: =IF($AC2="","",IFERROR(INDEX(Giocatori!$A:$A,MATCH($AC2,Giocatori!$AT:$AT,0)),"")) | B2: Yan Couto | D2: Como | E2: 24 | F2: 1 | G2: 4 | H2: 1 | I2: 4 | J2: 0 | K2: 1 | O2: obiettivo mercato | P2: 0 | Q2: 0 | R2: 6.38 | T2: 6.5 | V2: stima da presenze | W2: Semi-top | X2: 15-29 | Y2: 7.2 | AC2: 94914
A3: =IF($AC3="","",IFERROR(INDEX(Giocatori!$A:$A,MATCH($AC3,Giocatori!$AT:$AT,0)),"")) | B3: Alex Valle | D3: Como | E3: 22 | F3: 1 | G3: 3 | H3: 0.75 | I3: 3 | J3: 0 | K3: 1 | L3: 28 | M3: 1 | N3: 4 | O3: obiettivo mercato | P3: 0 | Q3: 0 | R3: 6.67 | S3: 6.19 | T3: 6.83 | U3: 6.31 | V3: stima da presenze | W3: Semi-top | X3: 15-29 | Y3: 7.14 | AC3: 115890
A4: =IF($AC4="","",IFERROR(INDEX(Giocatori!$A:$A,MATCH($AC4,Giocatori!$AT:$AT,0)),"")) | B4: Jacobo Ramon | D4: Como | E4: 21 | F4: 1 | G4: 4 | H4: 1 | I4: 4 | J4: 1 | K4: 0 | L4: 32 | M4: 2 | N4: 0 | O4: obiettivo mercato | P4: 0 | Q4: 0 | R4: 6.5 | S4: 6.16 | T4: 7.25 | U4: 6.14 | V4: stima da presenze | W4: Semi-top | X4: 15-29 | Y4: 7.14 | AC4: 119152
A5: =IF($AC5="","",IFERROR(INDEX(Giocatori!$A:$A,MATCH($AC5,Giocatori!$AT:$AT,0)),"")) | B5: Chalobah | D5: Como | E5: 27 | F5: 1 | G5: 3 | H5: 0.75 | I5: 3 | J5: 0 | K5: 0 | O5: obiettivo mercato | P5: 0 | Q5: 0 | R5: 6.33 | T5: 6.33 | V5: stima da presenze | W5: Medio | X5: 5-14 | Y5: 7.03 | AC5: 95318
A6: =IF($AC6="","",IFERROR(INDEX(Giocatori!$A:$A,MATCH($AC6,Giocatori!$AT:$AT,0)),""))
A7: =IF($AC7="","",IFERROR(INDEX(Giocatori!$A:$A,MATCH($AC7,Giocatori!$AT:$AT,0)),"")) | B7: Valeri | D7: Parma | E7: 28 | F7: 1 | G7: 4 | H7: 1 | I7: 4 | J7: 0 | K7: 0 | L7: 34 | M7: 0 | N7: 2 | P7: 2 | Q7: 3 | R7: 6 | S7: 6.18 | T7: 6 | U7: 6.18 | V7: probabili formazioni | W7: Medio | X7: 5-14 | Y7: 7.03 | AC7: 102062
A8: =IF($AC8="","",IFERROR(INDEX(Giocatori!$A:$A,MATCH($AC8,Giocatori!$AT:$AT,0)),"")) | B8: Dimarco | D8: Inter | E8: 29 | F8: 1 | G8: 3 | H8: 0.75 | I8: 4 | J8: 0 | K8: 1 | L8: 35 | M8: 7 | N8: 16 | P8: 0 | Q8: 2 | R8: 6.62 | S8: 6.9 | T8: 6.75 | U8: 7.72 | V8: probabili formazioni | W8: Top | X8: 30-50 | Y8: 8.17 | AC8: 49778
A9: =IF($AC9="","",IFERROR(INDEX(Giocatori!$A:$A,MATCH($AC9,Giocatori!$AT:$AT,0)),"")) | B9: Bisseck | D9: Inter | E9: 26 | F9: 1 | G9: 2 | H9: 0.5 | I9: 3 | J9: 1 | K9: 0 | L9: 23 | M9: 3 | N9: 1 | P9: 0 | Q9: 0 | R9: 6.75 | S9: 6.44 | T9: 8.25 | U9: 6.83 | V9: probabili formazioni | W9: Top | X9: 30-50 | Y9: 7.93 | AC9: 117151
A10: =IF($AC10="","",IFERROR(INDEX(Giocatori!$A:$A,MATCH($AC10,Giocatori!$AT:$AT,0)),"")) | B10: Bracaglia | D10: Frosinone | E10: 23 | F10: 1 | G10: 4 | H10: 1 | I10: 4 | J10: 1 | K10: 1 | P10: 0 | Q10: 0 | R10: 6.5 | T10: 7.12 | V10: probabili formazioni | W10: Top | X10: 30-50 | Y10: 7.82 | AC10: 115179
A11: =IF($AC11="","",IFERROR(INDEX(Giocatori!$A:$A,MATCH($AC11,Giocatori!$AT:$AT,0)),"")) | B11: Bremer | D11: Juventus | E11: 29 | F11: 1 | G11: 4 | H11: 1 | I11: 4 | J11: 1 | K11: 0 | L11: 26 | M11: 4 | N11: 3 | P11: 0 | Q11: 0 | R11: 6.38 | S11: 6.31 | T11: 7.38 | U11: 6.81 | V11: probabili formazioni | W11: Top | X11: 30-50 | Y11: 7.69 | AC11: 67789
A12: =IF($AC12="","",IFERROR(INDEX(Giocatori!$A:$A,MATCH($AC12,Giocatori!$AT:$AT,0)),"")) | B12: Abankwah | D12: Udinese | E12: 22 | F12: 1 | G12: 4 | H12: 1 | I12: 4 | J12: 1 | K12: 0 | P12: 0 | Q12: 0 | R12: 6.25 | T12: 6.88 | V12: probabili formazioni | W12: Semi-top | X12: 15-29 | Y12: 7.58 | AC12: 115130
A13: =IF($AC13="","",IFERROR(INDEX(Giocatori!$A:$A,MATCH($AC13,Giocatori!$AT:$AT,0)),"")) | B13: Wesley | D13: Roma | E13: 23 | F13: 1 | G13: 3 | H13: 0.75 | I13: 3 | J13: 0 | K13: 1 | L13: 30 | M13: 5 | N13: 0 | P13: 0 | Q13: 0 | R13: 6.67 | S13: 6.4 | T13: 6.83 | U13: 6.82 | V13: probabili formazioni | W13: Semi-top | X13: 15-29 | Y13: 7.52 | AC13: 119945
A14: =IF($AC14="","",IFERROR(INDEX(Giocatori!$A:$A,MATCH($AC14,Giocatori!$AT:$AT,0)),"")) | B14: Oyono | D14: Frosinone | E14: 25 | F14: 1 | G14: 3 | H14: 0.75 | I14: 4 | J14: 0 | K14: 1 | P14: 0 | Q14: 0 | R14: 6.62 | T14: 6.62 | V14: probabili formazioni | W14: Semi-top | X14: 15-29 | Y14: 7.32 | AC14: 113048
A15: =IF($AC15="","",IFERROR(INDEX(Giocatori!$A:$A,MATCH($AC15,Giocatori!$AT:$AT,0)),"")) | B15: Scalvini | D15: Atalanta | E15: 23 | F15: 1 | G15: 4 | H15: 1 | I15: 4 | J15: 0 | K15: 0 | L15: 24 | M15: 3 | N15: 1 | P15: 0 | Q15: 0 | R15: 6.12 | S15: 6.38 | T15: 6.12 | U15: 6.81 | V15: probabili formazioni | W15: Semi-top | X15: 15-29 | Y15: 7.28 | AC15: 102886
A16: =IF($AC16="","",IFERROR(INDEX(Giocatori!$A:$A,MATCH($AC16,Giocatori!$AT:$AT,0)),"")) | B16: Tiago Gabriel | D16: Lecce | E16: 22 | F16: 1 | G16: 3 | H16: 0.75 | I16: 4 | J16: 2 | K16: 0 | L16: 37 | M16: 2 | N16: 0 | P16: 0 | Q16: 0 | R16: 6.62 | S16: 6 | T16: 8.12 | U16: 6.03 | V16: probabili formazioni | W16: Semi-top | X16: 15-29 | Y16: 7.24 | AC16: 119838
A17: =IF($AC17="","",IFERROR(INDEX(Giocatori!$A:$A,MATCH($AC17,Giocatori!$AT:$AT,0)),"")) | B17: Bastoni | D17: Inter | E17: 27 | F17: 1 | G17: 4 | H17: 1 | I17: 4 | J17: 0 | K17: 0 | L17: 28 | M17: 1 | N17: 4 | P17: 0 | Q17: 0 | R17: 6.38 | S17: 6.41 | T17: 6.38 | U17: 6.52 | V17: probabili formazioni | W17: Semi-top | X17: 15-29 | Y17: 7.18 | AC17: 61306
A18: =IF($AC18="","",IFERROR(INDEX(Giocatori!$A:$A,MATCH($AC18,Giocatori!$AT:$AT,0)),"")) | B18: Mario Hermoso | D18: Roma | E18: 31 | F18: 1 | G18: 4 | H18: 1 | I18: 4 | J18: 1 | K18: 0 | L18: 27 | M18: 3 | N18: 2 | P18: 0 | Q18: 0 | R18: 6.88 | S18: 6.11 | T18: 7.38 | U18: 6.33 | V18: probabili formazioni | W18: Semi-top | X18: 15-29 | Y18: 7.15 | AC18: 63346
A19: =IF($AC19="","",IFERROR(INDEX(Giocatori!$A:$A,MATCH($AC19,Giocatori!$AT:$AT,0)),"")) | B19: Mancini | D19: Roma | E19: 30 | F19: 1 | G19: 4 | H19: 1 | I19: 4 | J19: 0 | K19: 1 | L19: 36 | M19: 4 | N19: 2 | P19: 0 | Q19: 0 | R19: 6.88 | S19: 6.22 | T19: 7 | U19: 6.51 | V19: probabili formazioni | W19: Semi-top | X19: 15-29 | Y19: 7.13 | AC19: 49438
A20: =IF($AC20="","",IFERROR(INDEX(Giocatori!$A:$A,MATCH($AC20,Giocatori!$AT:$AT,0)),"")) | B20: Pavlovic | D20: Milan | E20: 25 | F20: 1 | G20: 4 | H20: 1 | I20: 4 | J20: 0 | K20: 0 | L20: 34 | M20: 5 | N20: 1 | P20: 0 | Q20: 0 | R20: 6.12 | S20: 6.17 | T20: 5.88 | U20: 6.61 | V20: probabili formazioni | W20: Semi-top | X20: 15-29 | Y20: 7.12 | AC20: 70846
A21: =IF($AC21="","",IFERROR(INDEX(Giocatori!$A:$A,MATCH($AC21,Giocatori!$AT:$AT,0)),"")) | B21: Kalulu | D21: Juventus | E21: 26 | F21: 1 | G21: 4 | H21: 1 | I21: 4 | J21: 0 | K21: 0 | L21: 37 | M21: 2 | N21: 4 | P21: 0 | Q21: 0 | R21: 6.38 | S21: 6.22 | T21: 6.38 | U21: 6.42 | V21: probabili formazioni | W21: Semi-top | X21: 15-29 | Y21: 7.11 | AC21: 101889
A22: =IF($AC22="","",IFERROR(INDEX(Giocatori!$A:$A,MATCH($AC22,Giocatori!$AT:$AT,0)),"")) | B22: Lulli | D22: Roma | E22: 19 | F22: 1 | G22: 4 | H22: 1 | I22: 4 | J22: 0 | K22: 0 | P22: 0 | Q22: 0 | R22: 6.38 | T22: 6.38 | V22: probabili formazioni | W22: Semi-top | X22: 15-29 | Y22: 7.08 | AC22: 120128
A23: =IF($AC23="","",IFERROR(INDEX(Giocatori!$A:$A,MATCH($AC23,Giocatori!$AT:$AT,0)),"")) | B23: Comert | D23: Torino | E23: 28 | F23: 1 | G23: 3 | H23: 0.75 | I23: 3 | J23: 0 | K23: 1 | P23: 0 | Q23: 0 | R23: 6.17 | T23: 6.33 | V23: probabili formazioni | W23: Medio | X23: 5-14 | Y23: 7.03 | AC23: 54144
A24: =IF($AC24="","",IFERROR(INDEX(Giocatori!$A:$A,MATCH($AC24,Giocatori!$AT:$AT,0)),"")) | B24: Celik | D24: Juventus | E24: 29 | F24: 1 | G24: 4 | H24: 1 | I24: 4 | J24: 0 | K24: 0 | L24: 34 | M24: 1 | N24: 2 | P24: 0 | Q24: 0 | R24: 6.38 | S24: 6.26 | T24: 6.25 | U24: 6.32 | V24: probabili formazioni | W24: Medio | X24: 5-14 | Y24: 7 | AC24: 66280
A25: =IF($AC25="","",IFERROR(INDEX(Giocatori!$A:$A,MATCH($AC25,Giocatori!$AT:$AT,0)),"")) | B25: Doig | D25: Sassuolo | E25: 24 | F25: 1 | G25: 4 | H25: 1 | I25: 4 | J25: 1 | K25: 0 | L25: 30 | M25: 0 | N25: 0 | P25: 0 | Q25: 0 | R25: 6.75 | S25: 5.89 | T25: 7.5 | U25: 5.8 | V25: probabili formazioni | W25: Medio | X25: 5-14 | Y25: 6.99 | AC25: 114323
A26: =IF($AC26="","",IFERROR(INDEX(Giocatori!$A:$A,MATCH($AC26,Giocatori!$AT:$AT,0)),"")) | B26: Juan Miranda | D26: Bologna | E26: 26 | F26: 1 | G26: 2 | H26: 0.5 | I26: 3 | J26: 0 | K26: 1 | L26: 32 | M26: 1 | N26: 3 | P26: 0 | Q26: 0 | R26: 6.17 | S26: 6.23 | T26: 6.33 | U26: 6.27 | V26: probabili formazioni | W26: Medio | X26: 5-14 | Y26: 6.98 | AC26: 66177
A27: =IF($AC27="","",IFERROR(INDEX(Giocatori!$A:$A,MATCH($AC27,Giocatori!$AT:$AT,0)),""))
A28: =IF($AC28="","",IFERROR(INDEX(Giocatori!$A:$A,MATCH($AC28,Giocatori!$AT:$AT,0)),"")) | B28: SQUADRE MINORI (titolari)
A29: =IF($AC29="","",IFERROR(INDEX(Giocatori!$A:$A,MATCH($AC29,Giocatori!$AT:$AT,0)),"")) | B29: Comuzzo | D29: Torino | E29: 21 | F29: 1 | G29: 4 | H29: 1 | I29: 4 | J29: 1 | K29: 0 | L29: 27 | M29: 1 | N29: 0 | P29: 0 | Q29: 0 | R29: 6.25 | S29: 5.94 | T29: 7 | U29: 5.94 | V29: probabili formazioni | W29: Medio | X29: 5-14 | Y29: 6.97 | AC29: 118201
A30: =IF($AC30="","",IFERROR(INDEX(Giocatori!$A:$A,MATCH($AC30,Giocatori!$AT:$AT,0)),"")) | B30: Birindelli | D30: Monza | E30: 27 | F30: 1 | G30: 4 | H30: 1 | I30: 4 | J30: 0 | K30: 1 | P30: 0 | Q30: 0 | R30: 6.12 | T30: 6.25 | V30: probabili formazioni | W30: Medio | X30: 5-14 | Y30: 6.95 | AC30: 61216
A31: =IF($AC31="","",IFERROR(INDEX(Giocatori!$A:$A,MATCH($AC31,Giocatori!$AT:$AT,0)),"")) | B31: Rodriguez | D31: Cagliari | E31: 21 | F31: 1 | G31: 4 | H31: 1 | I31: 4 | J31: 0 | K31: 0 | L31: 17 | M31: 1 | N31: 0 | P31: 0 | Q31: 0 | R31: 6.25 | S31: 6.03 | T31: 6.25 | U31: 6.19 | V31: probabili formazioni | W31: Medio | X31: 5-14 | Y31: 6.91 | AC31: 119654
A32: =IF($AC32="","",IFERROR(INDEX(Giocatori!$A:$A,MATCH($AC32,Giocatori!$AT:$AT,0)),"")) | B32: Kamara | D32: Udinese | E32: 32 | F32: 1 | G32: 4 | H32: 1 | I32: 4 | J32: 2 | K32: 1 | L32: 26 | M32: 0 | N32: 2 | P32: 0 | Q32: 0 | R32: 6.75 | S32: 6 | T32: 8.38 | U32: 5.94 | V32: probabili formazioni | W32: Medio | X32: 5-14 | Y32: 6.91 | AC32: 56975
A33: =IF($AC33="","",IFERROR(INDEX(Giocatori!$A:$A,MATCH($AC33,Giocatori!$AT:$AT,0)),"")) | B33: Østigård | D33: Genoa | E33: 27 | F33: 1 | G33: 4 | H33: 1 | I33: 4 | J33: 0 | K33: 0 | L33: 30 | M33: 5 | N33: 1 | P33: 0 | Q33: 0 | R33: 5.62 | S33: 6.1 | T33: 5.25 | U33: 6.53 | V33: probabili formazioni | W33: Medio | X33: 5-14 | Y33: 6.86 | AC33: 109993
A34: =IF($AC34="","",IFERROR(INDEX(Giocatori!$A:$A,MATCH($AC34,Giocatori!$AT:$AT,0)),"")) | B34: Obert | D34: Cagliari | E34: 24 | F34: 1 | G34: 4 | H34: 1 | I34: 4 | J34: 0 | K34: 0 | L34: 35 | M34: 0 | N34: 3 | P34: 0 | Q34: 0 | R34: 6.62 | S34: 6.06 | T34: 6.62 | U34: 5.96 | V34: probabili formazioni | W34: Medio | X34: 5-14 | Y34: 6.83 | AC34: 110625
A35: =IF($AC35="","",IFERROR(INDEX(Giocatori!$A:$A,MATCH($AC35,Giocatori!$AT:$AT,0)),"")) | B35: Cittadini | D35: Frosinone | E35: 24 | F35: 1 | G35: 3 | H35: 0.75 | I35: 4 | J35: 0 | K35: 0 | P35: 0 | Q35: 0 | R35: 6.25 | T35: 6.12 | V35: probabili formazioni | W35: Medio | X35: 5-14 | Y35: 6.82 | AC35: 112395
A36: =IF($AC36="","",IFERROR(INDEX(Giocatori!$A:$A,MATCH($AC36,Giocatori!$AT:$AT,0)),"")) | B36: Leysen | D36: Sassuolo | E36: 23 | F36: 1 | G36: 3 | H36: 0.75 | I36: 4 | J36: 0 | K36: 1 | P36: 0 | Q36: 0 | R36: 6.12 | T36: 6.12 | V36: probabili formazioni | W36: Medio | X36: 5-14 | Y36: 6.82 | AC36: 116659
A37: =IF($AC37="","",IFERROR(INDEX(Giocatori!$A:$A,MATCH($AC37,Giocatori!$AT:$AT,0)),"")) | B37: Vojvoda | D37: Udinese | E37: 31 | F37: 1 | G37: 4 | H37: 1 | I37: 4 | J37: 0 | K37: 0 | L37: 30 | M37: 2 | N37: 2 | P37: 0 | Q37: 0 | R37: 6.12 | S37: 6.11 | T37: 6.12 | U37: 6.39 | V37: probabili formazioni | W37: Medio | X37: 5-14 | Y37: 6.81 | AC37: 71540
A38: =IF($AC38="","",IFERROR(INDEX(Giocatori!$A:$A,MATCH($AC38,Giocatori!$AT:$AT,0)),"")) | B38: Saul Coco | D38: Torino | E38: 27 | F38: 1 | G38: 4 | H38: 1 | I38: 4 | J38: 0 | K38: 0 | L38: 35 | M38: 1 | N38: 1 | P38: 0 | Q38: 0 | R38: 5.88 | S38: 6.07 | T38: 5.88 | U38: 6.13 | V38: probabili formazioni | W38: Medio | X38: 5-14 | Y38: 6.77 | AC38: 117029

Sheet Centrocampisti
A1: venduto | B1: nome | C1: soprannome | D1: squadra | E1: eta | F1: titolare | G1: da_titolare | H1: pct_titolare | I1: presenze | J1: gol | K1: assist | L1: presenze_prev | M1: gol_prev | N1: assist_prev | O1: assist_tot | P1: obiettivo | Q1: bomber | R1: rigorista | S1: piazzati | T1: fm | U1: fm_prev | V1: mv | W1: mv_prev | X1: titolare_fonte | Y1: fascia | Z1: prezzo_indicativo | AA1: punteggio | AB1: indisponibile | AC1: rientro_data | AD1: stop_lungo | AE1: id
A2: =IF($AE2="","",IFERROR(INDEX(Giocatori!$A:$A,MATCH($AE2,Giocatori!$AT:$AT,0)),"")) | B2: Ilic | D2: Lecce | E2: 25 | F2: 0 | G2: 2 | H2: 0.5 | I2: 3 | J2: 0 | K2: 2 | L2: 8 | M2: 0 | N2: 0 | O2: 2 | P2: sesto centrocampista | R2: 0 | S2: 0 | T2: 6.67 | U2: 5.62 | V2: 6.5 | W2: 5.75 | Y2: Scommessa | Z2: 1-9 | AA2: 6.38 | AE2: 100764
A3: =IF($AE3="","",IFERROR(INDEX(Giocatori!$A:$A,MATCH($AE3,Giocatori!$AT:$AT,0)),"")) | B3: Matic | D3: Sassuolo | E3: 38 | F3: 1 | G3: 4 | H3: 1 | I3: 4 | J3: 0 | K3: 1 | L3: 34 | M3: 1 | N3: 1 | O3: 2 | P3: obiettivo mercato | R3: 0 | S3: 0 | T3: 6.25 | U3: 6.06 | V3: 6.25 | W3: 6.07 | X3: probabili formazioni | Y3: Scommessa | Z3: 1-9 | AA3: 6.31 | AE3: 19997
A4: =IF($AE4="","",IFERROR(INDEX(Giocatori!$A:$A,MATCH($AE4,Giocatori!$AT:$AT,0)),"")) | B4: Rabiot | D4: Milan | E4: 31 | F4: 1 | G4: 2 | H4: 0.5 | I4: 4 | J4: 1 | K4: 2 | L4: 29 | M4: 6 | N4: 4 | O4: 6 | P4: obiettivo | Q4: sì | R4: 0 | S4: 0 | T4: 7.75 | U4: 7 | V4: 6.5 | W4: 6.37 | X4: probabili formazioni | Y4: Medio | Z4: 10-29 | AA4: 7.72 | AE4: 38053
A5: =IF($AE5="","",IFERROR(INDEX(Giocatori!$A:$A,MATCH($AE5,Giocatori!$AT:$AT,0)),"")) | B5: Pisilli | D5: Roma | E5: 22 | F5: 0 | G5: 1 | H5: 0.25 | I5: 3 | J5: 2 | K5: 0 | L5: 25 | M5: 2 | N5: 4 | O5: 4 | P5: obiettivo | R5: 0 | S5: 0 | T5: 8.67 | U5: 6.57 | V5: 6.83 | W5: 6.28 | Y5: Semi-top | Z5: 30-59 | AA5: 7.93 | AE5: 116597
A6: =IF($AE6="","",IFERROR(INDEX(Giocatori!$A:$A,MATCH($AE6,Giocatori!$AT:$AT,0)),"")) | B6: Fagioli | D6: Fiorentina | E6: 25 | F6: 1 | G6: 3 | H6: 0.75 | I6: 4 | J6: 0 | K6: 1 | L6: 33 | M6: 2 | N6: 3 | O6: 4 | P6: obiettivo | R6: 0 | S6: 0 | T6: 6.25 | U6: 6.41 | V6: 6.25 | W6: 6.23 | X6: probabili formazioni | Y6: Medio | Z6: 10-29 | AA6: 7.07 | AE6: 103752
A7: =IF($AE7="","",IFERROR(INDEX(Giocatori!$A:$A,MATCH($AE7,Giocatori!$AT:$AT,0)),"")) | B7: Diouf | D7: Inter | E7: 23 | F7: 1 | G7: 3 | H7: 0.75 | I7: 3 | J7: 0 | K7: 3 | L7: 19 | M7: 1 | N7: 0 | O7: 3 | P7: obiettivo | R7: 0 | S7: 0 | T7: 7.67 | U7: 6.31 | V7: 7.17 | W7: 6.08 | X7: probabili formazioni | Y7: Semi-top | Z7: 30-59 | AA7: 7.75 | AE7: 109651
A8: =IF($AE8="","",IFERROR(INDEX(Giocatori!$A:$A,MATCH($AE8,Giocatori!$AT:$AT,0)),"")) | B8: Moreira | D8: Milan | E8: 22 | F8: 0 | G8: 1 | H8: 0.25 | I8: 2 | J8: 2 | K8: 0 | O8: 0 | P8: obiettivo | R8: 0 | S8: 0 | T8: 10 | V8: 6.75 | Y8: Top | Z8: 60-100 | AA8: 10.2 | AE8: 113444
A9: =IF($AE9="","",IFERROR(INDEX(Giocatori!$A:$A,MATCH($AE9,Giocatori!$AT:$AT,0)),"")) | B9: Mastantuono | D9: Fiorentina | E9: 19 | F9: 1 | G9: 4 | H9: 1 | I9: 4 | J9: 3 | K9: 0 | O9: 0 | P9: obiettivo | R9: 0 | S9: 1 | T9: 9 | V9: 6.75 | X9: probabili formazioni | Y9: Top | Z9: 60-100 | AA9: 9.8 | AE9: 120530
A10: =IF($AE10="","",IFERROR(INDEX(Giocatori!$A:$A,MATCH($AE10,Giocatori!$AT:$AT,0)),""))
A11: =IF($AE11="","",IFERROR(INDEX(Giocatori!$A:$A,MATCH($AE11,Giocatori!$AT:$AT,0)),"")) | B11: Barella | D11: Inter | E11: 29 | F11: 1 | G11: 4 | H11: 1 | I11: 4 | J11: 1 | K11: 1 | L11: 34 | M11: 3 | N11: 8 | O11: 9 | R11: 0 | S11: 0 | T11: 8 | U11: 6.68 | V11: 7.12 | W11: 6.4 | X11: probabili formazioni | Y11: Semi-top | Z11: 30-59 | AA11: 8.02 | AE11: 45456
A12: =IF($AE12="","",IFERROR(INDEX(Giocatori!$A:$A,MATCH($AE12,Giocatori!$AT:$AT,0)),"")) | B12: Paz | D12: Como | E12: 22 | F12: 1 | G12: 4 | H12: 1 | I12: 4 | J12: 1 | K12: 1 | L12: 35 | M12: 12 | N12: 6 | O12: 7 | Q12: sì | R12: 0 | S12: 1 | T12: 7.5 | U12: 7.36 | V12: 6.62 | W12: 6.46 | X12: stima da presenze | Y12: Top | Z12: 60-100 | AA12: 8.8 | AE12: 116105
A13: =IF($AE13="","",IFERROR(INDEX(Giocatori!$A:$A,MATCH($AE13,Giocatori!$AT:$AT,0)),"")) | B13: Francisco Conceicao | D13: Juventus | E13: 24 | F13: 1 | G13: 4 | H13: 1 | I13: 4 | J13: 0 | K13: 1 | L13: 31 | M13: 3 | N13: 5 | O13: 6 | R13: 0 | S13: 0 | T13: 6.75 | U13: 6.55 | V13: 6.62 | W13: 6.23 | X13: probabili formazioni | Y13: Medio | Z13: 10-29 | AA13: 7.31 | AE13: 104526
A14: =IF($AE14="","",IFERROR(INDEX(Giocatori!$A:$A,MATCH($AE14,Giocatori!$AT:$AT,0)),"")) | B14: Pulisic | D14: Milan | E14: 28 | F14: 1 | G14: 0 | H14: 0 | I14: 1 | J14: 0 | K14: 1 | L14: 30 | M14: 8 | N14: 4 | O14: 5 | Q14: sì | R14: 2 | S14: 2 | T14: 7 | U14: 7.21 | V14: 7 | W14: 6.31 | X14: probabili formazioni | Y14: Semi-top | Z14: 30-59 | AA14: 8.09 | AE14: 53448
A15: =IF($AE15="","",IFERROR(INDEX(Giocatori!$A:$A,MATCH($AE15,Giocatori!$AT:$AT,0)),"")) | B15: Perrone | D15: Como | E15: 23 | F15: 1 | G15: 3 | H15: 0.75 | I15: 4 | J15: 0 | K15: 1 | L15: 36 | M15: 3 | N15: 4 | O15: 5 | R15: 0 | S15: 0 | T15: 6.5 | U15: 6.5 | V15: 6.38 | W15: 6.26 | X15: stima da presenze | Y15: Semi-top | Z15: 30-59 | AA15: 7.8 | AE15: 116309
A16: =IF($AE16="","",IFERROR(INDEX(Giocatori!$A:$A,MATCH($AE16,Giocatori!$AT:$AT,0)),"")) | B16: Gaetano | D16: Atalanta | E16: 26 | F16: 1 | G16: 3 | H16: 0.75 | I16: 3 | J16: 0 | K16: 1 | L16: 33 | M16: 2 | N16: 4 | O16: 5 | R16: 0 | S16: 3 | T16: 6.33 | U16: 6.39 | V16: 6.5 | W16: 6.17 | X16: probabili formazioni | Y16: Medio | Z16: 10-29 | AA16: 7.08 | AE16: 67792
A17: =IF($AE17="","",IFERROR(INDEX(Giocatori!$A:$A,MATCH($AE17,Giocatori!$AT:$AT,0)),"")) | B17: Politano | D17: Napoli | E17: 33 | F17: 1 | G17: 4 | H17: 1 | I17: 4 | J17: 1 | K17: 0 | L17: 34 | M17: 2 | N17: 5 | O17: 5 | R17: 3 | S17: 2 | T17: 6.88 | U17: 6.44 | V17: 6.25 | W17: 6.19 | X17: probabili formazioni | Y17: Scommessa | Z17: 1-9 | AA17: 6.75 | AE17: 40864
A18: =IF($AE18="","",IFERROR(INDEX(Giocatori!$A:$A,MATCH($AE18,Giocatori!$AT:$AT,0)),"")) | B18: Baturina | D18: Como | E18: 23 | F18: 1 | G18: 4 | H18: 1 | I18: 4 | J18: 2 | K18: 1 | L18: 29 | M18: 6 | N18: 3 | O18: 4 | Q18: sì | R18: 0 | S18: 2 | T18: 8.38 | U18: 7.22 | V18: 6.88 | W18: 6.44 | X18: stima da presenze | Y18: Top | Z18: 60-100 | AA18: 8.86 | AE18: 103455
A19: =IF($AE19="","",IFERROR(INDEX(Giocatori!$A:$A,MATCH($AE19,Giocatori!$AT:$AT,0)),"")) | B19: da Cunha | D19: Como | E19: 25 | F19: 1 | G19: 3 | H19: 0.75 | I19: 4 | J19: 0 | K19: 0 | L19: 36 | M19: 6 | N19: 4 | O19: 4 | Q19: sì | R19: 1 | S19: 0 | T19: 6.38 | U19: 7.01 | V19: 6.38 | W19: 6.46 | X19: stima da presenze | Y19: Top | Z19: 60-100 | AA19: 8.65 | AE19: 73202
A20: =IF($AE20="","",IFERROR(INDEX(Giocatori!$A:$A,MATCH($AE20,Giocatori!$AT:$AT,0)),"")) | B20: Ekkelenkamp | D20: Udinese | E20: 26 | F20: 1 | G20: 4 | H20: 1 | I20: 4 | J20: 2 | K20: 1 | L20: 31 | M20: 5 | N20: 3 | O20: 4 | Q20: sì | R20: 0 | S20: 2 | T20: 8.38 | U20: 6.9 | V20: 6.5 | W20: 6.26 | X20: probabili formazioni | Y20: Semi-top | Z20: 30-59 | AA20: 8.01 | AE20: 66186
A21: =IF($AE21="","",IFERROR(INDEX(Giocatori!$A:$A,MATCH($AE21,Giocatori!$AT:$AT,0)),"")) | B21: Zielinski | D21: Inter | E21: 32 | F21: 1 | G21: 3 | H21: 0.75 | I21: 4 | J21: 1 | K21: 1 | L21: 34 | M21: 6 | N21: 3 | O21: 4 | Q21: sì | R21: 2 | S21: 3 | T21: 7.88 | U21: 6.97 | V21: 6.75 | W21: 6.4 | X21: probabili formazioni | Y21: Semi-top | Z21: 30-59 | AA21: 7.91 | AE21: 38482
A22: =IF($AE22="","",IFERROR(INDEX(Giocatori!$A:$A,MATCH($AE22,Giocatori!$AT:$AT,0)),"")) | B22: Adopo | D22: Cagliari | E22: 26 | F22: 1 | G22: 4 | H22: 1 | I22: 4 | J22: 0 | K22: 2 | L22: 38 | M22: 1 | N22: 2 | O22: 4 | R22: 0 | S22: 0 | T22: 6.88 | U22: 6.21 | V22: 6.62 | W22: 6.16 | X22: probabili formazioni | Y22: Medio | Z22: 10-29 | AA22: 7.07 | AE22: 66457
A23: =IF($AE23="","",IFERROR(INDEX(Giocatori!$A:$A,MATCH($AE23,Giocatori!$AT:$AT,0)),"")) | B23: De Bruyne | D23: Napoli | E23: 35 | F23: 1 | G23: 1 | H23: 0.25 | I23: 4 | J23: 1 | K23: 1 | L23: 18 | M23: 5 | N23: 2 | O23: 3 | Q23: sì | R23: 1 | S23: 1 | T23: 7.88 | U23: 7.32 | V23: 6.75 | W23: 6.5 | X23: probabili formazioni | Y23: Semi-top | Z23: 30-59 | AA23: 8.34 | AE23: 19157
A24: =IF($AE24="","",IFERROR(INDEX(Giocatori!$A:$A,MATCH($AE24,Giocatori!$AT:$AT,0)),"")) | B24: Vlasic | D24: Torino | E24: 29 | F24: 1 | G24: 4 | H24: 1 | I24: 4 | J24: 0 | K24: 0 | L24: 37 | M24: 8 | N24: 3 | O24: 3 | Q24: sì | R24: 1 | S24: 1 | T24: 6.12 | U24: 6.93 | V24: 6.12 | W24: 6.27 | X24: probabili formazioni | Y24: Semi-top | Z24: 30-59 | AA24: 8.03 | AE24: 46949
A25: =IF($AE25="","",IFERROR(INDEX(Giocatori!$A:$A,MATCH($AE25,Giocatori!$AT:$AT,0)),"")) | B25: Kone | D25: Roma | E25: 25 | F25: 1 | G25: 3 | H25: 0.75 | I25: 4 | J25: 0 | K25: 0 | L25: 29 | M25: 2 | N25: 3 | O25: 3 | R25: 0 | S25: 0 | T25: 6.12 | U25: 6.57 | V25: 6.25 | W25: 6.28 | X25: probabili formazioni | Y25: Semi-top | Z25: 30-59 | AA25: 7.74 | AE25: 70392
A26: =IF($AE26="","",IFERROR(INDEX(Giocatori!$A:$A,MATCH($AE26,Giocatori!$AT:$AT,0)),"")) | B26: Atta | D26: Fiorentina | E26: 23 | F26: 1 | G26: 3 | H26: 0.75 | I26: 4 | J26: 0 | K26: 0 | L26: 32 | M26: 5 | N26: 3 | O26: 3 | Q26: sì | R26: 0 | S26: 2 | T26: 6.12 | U26: 6.77 | V26: 6.12 | W26: 6.27 | X26: probabili formazioni | Y26: Medio | Z26: 10-29 | AA26: 7.29 | AE26: 117169
A27: =IF($AE27="","",IFERROR(INDEX(Giocatori!$A:$A,MATCH($AE27,Giocatori!$AT:$AT,0)),""))
A28: =IF($AE28="","",IFERROR(INDEX(Giocatori!$A:$A,MATCH($AE28,Giocatori!$AT:$AT,0)),"")) | B28: SQUADRE MINORI (titolari)
A29: =IF($AE29="","",IFERROR(INDEX(Giocatori!$A:$A,MATCH($AE29,Giocatori!$AT:$AT,0)),"")) | B29: Adzic | D29: Sassuolo | E29: 20 | F29: 1 | G29: 3 | H29: 0.75 | I29: 4 | J29: 2 | K29: 1 | L29: 10 | M29: 1 | N29: 0 | O29: 1 | R29: 0 | S29: 3 | T29: 8.62 | U29: 7.1 | V29: 6.75 | W29: 6.3 | X29: probabili formazioni | Y29: Top | Z29: 60-100 | AA29: 8.63 | AE29: 117416
A30: =IF($AE30="","",IFERROR(INDEX(Giocatori!$A:$A,MATCH($AE30,Giocatori!$AT:$AT,0)),"")) | B30: Romano | D30: Cagliari | E30: 20 | F30: 1 | G30: 4 | H30: 1 | I30: 4 | J30: 1 | K30: 0 | O30: 0 | R30: 0 | S30: 3 | T30: 7.75 | V30: 6.75 | X30: probabili formazioni | Y30: Top | Z30: 60-100 | AA30: 8.45 | AE30: 119818
A31: =IF($AE31="","",IFERROR(INDEX(Giocatori!$A:$A,MATCH($AE31,Giocatori!$AT:$AT,0)),"")) | B31: Maldini | D31: Cagliari | E31: 25 | F31: 1 | G31: 4 | H31: 1 | I31: 4 | J31: 2 | K31: 0 | L31: 13 | M31: 2 | N31: 1 | O31: 1 | R31: 0 | S31: 2 | T31: 8.5 | U31: 6.58 | V31: 6.5 | W31: 6.19 | X31: probabili formazioni | Y31: Semi-top | Z31: 30-59 | AA31: 8.2 | AE31: 73082
A32: =IF($AE32="","",IFERROR(INDEX(Giocatori!$A:$A,MATCH($AE32,Giocatori!$AT:$AT,0)),"")) | B32: Calo | D32: Frosinone | E32: 29 | F32: 1 | G32: 4 | H32: 1 | I32: 4 | J32: 0 | K32: 1 | O32: 1 | Q32: sì | R32: 1 | S32: 1 | T32: 6.75 | V32: 6.62 | X32: probabili formazioni | Y32: Semi-top | Z32: 30-59 | AA32: 8.05 | AE32: 58637
A33: =IF($AE33="","",IFERROR(INDEX(Giocatori!$A:$A,MATCH($AE33,Giocatori!$AT:$AT,0)),"")) | B33: Hainaut | D33: Venezia | E33: 24 | F33: 1 | G33: 4 | H33: 1 | I33: 4 | J33: 1 | K33: 1 | O33: 1 | R33: 0 | S33: 0 | T33: 7.25 | V33: 6.38 | X33: probabili formazioni | Y33: Semi-top | Z33: 30-59 | AA33: 7.95 | AE33: 115181
A34: =IF($AE34="","",IFERROR(INDEX(Giocatori!$A:$A,MATCH($AE34,Giocatori!$AT:$AT,0)),"")) | B34: Colpani | D34: Monza | E34: 27 | F34: 1 | G34: 3 | H34: 0.75 | I34: 4 | J34: 1 | K34: 0 | O34: 0 | R34: 0 | S34: 0 | T34: 7 | V34: 6.25 | X34: probabili formazioni | Y34: Medio | Z34: 10-29 | AA34: 7.7 | AE34: 66512
A35: =IF($AE35="","",IFERROR(INDEX(Giocatori!$A:$A,MATCH($AE35,Giocatori!$AT:$AT,0)),"")) | B35: Coulibaly | D35: Lecce | E35: 30 | F35: 1 | G35: 4 | H35: 1 | I35: 4 | J35: 2 | K35: 1 | L35: 33 | M35: 3 | N35: 1 | O35: 2 | R35: 0 | S35: 0 | T35: 8.5 | U35: 6.32 | V35: 6.62 | W35: 6.09 | X35: probabili formazioni | Y35: Medio | Z35: 10-29 | AA35: 7.4 | AE35: 95265
A36: =IF($AE36="","",IFERROR(INDEX(Giocatori!$A:$A,MATCH($AE36,Giocatori!$AT:$AT,0)),"")) | B36: Unai Gomez | D36: Udinese | E36: 23 | F36: 1 | G36: 3 | H36: 0.75 | I36: 4 | J36: 0 | K36: 1 | O36: 1 | R36: 0 | S36: 3 | T36: 6.5 | V36: 6.33 | X36: probabili formazioni | Y36: Medio | Z36: 10-29 | AA36: 7.2 | AE36: 116835
A37: =IF($AE37="","",IFERROR(INDEX(Giocatori!$A:$A,MATCH($AE37,Giocatori!$AT:$AT,0)),"")) | B37: Adrian Bernabe | D37: Parma | E37: 25 | F37: 1 | G37: 2 | H37: 0.5 | I37: 3 | J37: 0 | K37: 0 | L37: 32 | M37: 3 | N37: 1 | O37: 1 | R37: 0 | S37: 0 | T37: 6 | U37: 6.56 | V37: 6 | W37: 6.27 | X37: probabili formazioni | Y37: Medio | Z37: 10-29 | AA37: 7.14 | AE37: 94911
A38: =IF($AE38="","",IFERROR(INDEX(Giocatori!$A:$A,MATCH($AE38,Giocatori!$AT:$AT,0)),"")) | B38: Cacciamani | D38: Torino | E38: 19 | F38: 1 | G38: 3 | H38: 0.75 | I38: 4 | J38: 0 | K38: 1 | O38: 1 | R38: 0 | S38: 0 | T38: 6.38 | V38: 6.25 | X38: probabili formazioni | Y38: Medio | Z38: 10-29 | AA38: 7.08 | AE38: 119874

Sheet Attaccanti
A1: venduto | B1: nome | C1: soprannome | D1: squadra | E1: eta | F1: titolare | G1: da_titolare | H1: pct_titolare | I1: presenze | J1: gol | K1: assist | L1: presenze_prev | M1: gol_prev | N1: assist_prev | O1: gol_proiettati | P1: obiettivo | Q1: squadra_prev | R1: cambiato_squadra | S1: rigorista | T1: fm | U1: fm_prev | V1: fascia | W1: prezzo_indicativo | X1: punteggio | Y1: indisponibile | Z1: rientro_data | AA1: stop_lungo | AB1: id
A2: =IF($AB2="","",IFERROR(INDEX(Giocatori!$A:$A,MATCH($AB2,Giocatori!$AT:$AT,0)),"")) | B2: Lauriente | D2: Sassuolo | E2: 28 | F2: 1 | G2: 4 | H2: 1 | I2: 4 | J2: 0 | K2: 1 | L2: 38 | M2: 7 | N2: 9 | O2: 0 | P2: quinta punta | Q2: Sassuolo | R2: 0 | S2: 3 | T2: 6.25 | U2: 6.88 | V2: Medio | W2: 15-49 | X2: 7.43 | AB2: 95435
A3: =IF($AB3="","",IFERROR(INDEX(Giocatori!$A:$A,MATCH($AB3,Giocatori!$AT:$AT,0)),"")) | B3: Malen | D3: Roma | E3: 27 | F3: 1 | G3: 4 | H3: 1 | I3: 4 | J3: 6 | K3: 0 | L3: 18 | M3: 14 | N3: 2 | O3: 57 | P3: obiettivo | Q3: Roma | R3: 0 | S3: 1 | T3: 12.5 | U3: 9.28 | V3: Top | W3: 110-180 | X3: 12.07 | AB3: 63371
A4: =IF($AB4="","",IFERROR(INDEX(Giocatori!$A:$A,MATCH($AB4,Giocatori!$AT:$AT,0)),""))
A5: =IF($AB5="","",IFERROR(INDEX(Giocatori!$A:$A,MATCH($AB5,Giocatori!$AT:$AT,0)),"")) | B5: Lautaro Martinez | C5: el Toro | D5: Inter | E5: 29 | F5: 1 | G5: 3 | H5: 0.75 | I5: 3 | J5: 2 | K5: 0 | L5: 30 | M5: 17 | N5: 6 | O5: 25.3 | Q5: Inter | R5: 0 | S5: 0 | T5: 8.5 | U5: 8.7 | V5: Top | W5: 110-180 | X5: 9.65 | AB5: 67777
A6: =IF($AB6="","",IFERROR(INDEX(Giocatori!$A:$A,MATCH($AB6,Giocatori!$AT:$AT,0)),"")) | B6: Douvikas | D6: Como | E6: 27 | F6: 1 | G6: 3 | H6: 0.75 | I6: 4 | J6: 2 | K6: 0 | L6: 38 | M6: 14 | N6: 1 | O6: 19 | Q6: Como 1907 | R6: 0 | S6: 3 | T6: 8.5 | U6: 7.67 | V6: Semi-top | W6: 50-109 | X6: 8.87 | AB6: 118290
A7: =IF($AB7="","",IFERROR(INDEX(Giocatori!$A:$A,MATCH($AB7,Giocatori!$AT:$AT,0)),"")) | B7: Thuram | D7: Inter | E7: 29 | F7: 1 | G7: 1 | H7: 0.25 | I7: 3 | J7: 2 | K7: 1 | L7: 29 | M7: 13 | N7: 6 | O7: 25.3 | Q7: Inter | R7: 0 | S7: 0 | T7: 9 | U7: 8 | V7: Semi-top | W7: 50-109 | X7: 9.24 | AB7: 63275
A8: =IF($AB8="","",IFERROR(INDEX(Giocatori!$A:$A,MATCH($AB8,Giocatori!$AT:$AT,0)),"")) | B8: Hojlund | D8: Napoli | E8: 23 | F8: 1 | G8: 4 | H8: 1 | I8: 4 | J8: 2 | K8: 0 | L8: 33 | M8: 12 | N8: 5 | O8: 19 | Q8: Napoli | R8: 0 | S8: 2 | T8: 7.88 | U8: 7.68 | V8: Semi-top | W8: 50-109 | X8: 8.63 | AB8: 102774
A9: =IF($AB9="","",IFERROR(INDEX(Giocatori!$A:$A,MATCH($AB9,Giocatori!$AT:$AT,0)),"")) | B9: Simeone | D9: Torino | E9: 31 | F9: 1 | G9: 3 | H9: 0.75 | I9: 4 | J9: 0 | K9: 0 | L9: 32 | M9: 11 | N9: 0 | O9: 0 | Q9: Torino | R9: 0 | S9: 2 | T9: 5.62 | U9: 7.3 | V9: Medio | W9: 15-49 | X9: 7.54 | AB9: 60802
A10: =IF($AB10="","",IFERROR(INDEX(Giocatori!$A:$A,MATCH($AB10,Giocatori!$AT:$AT,0)),"")) | B10: Scamacca | D10: Atalanta | E10: 27 | F10: 1 | G10: 4 | H10: 1 | I10: 4 | J10: 1 | K10: 0 | L10: 24 | M10: 10 | N10: 1 | O10: 9.5 | Q10: Atalanta | R10: 0 | S10: 1 | T10: 7.12 | U10: 7.61 | V10: Semi-top | W10: 50-109 | X10: 8.65 | AB10: 61870
A11: =IF($AB11="","",IFERROR(INDEX(Giocatori!$A:$A,MATCH($AB11,Giocatori!$AT:$AT,0)),"")) | B11: Davis | D11: Udinese | E11: 28 | F11: 1 | G11: 3 | H11: 0.75 | I11: 3 | J11: 0 | K11: 2 | L11: 30 | M11: 10 | N11: 4 | O11: 0 | Q11: Udinese | R11: 0 | S11: 1 | T11: 6.17 | U11: 7.22 | V11: Medio | W11: 15-49 | X11: 8.18 | AB11: 58086
A12: =IF($AB12="","",IFERROR(INDEX(Giocatori!$A:$A,MATCH($AB12,Giocatori!$AT:$AT,0)),"")) | B12: Krstovic | D12: Atalanta | E12: 26 | F12: 0 | G12: 0 | H12: 0 | I12: 4 | J12: 1 | K12: 0 | L12: 33 | M12: 10 | N12: 5 | O12: 9.5 | Q12: Atalanta | R12: 0 | S12: 2 | T12: 6.88 | U12: 7.31 | V12: Medio | W12: 15-49 | X12: 7.6 | AB12: 95769
A13: =IF($AB13="","",IFERROR(INDEX(Giocatori!$A:$A,MATCH($AB13,Giocatori!$AT:$AT,0)),"")) | B13: Yildiz | D13: Juventus | E13: 21 | F13: 0 | G13: 1 | H13: 0.25 | I13: 1 | J13: 0 | K13: 0 | L13: 36 | M13: 10 | N13: 6 | O13: 0 | Q13: Juventus | R13: 0 | S13: 0 | T13: 6.5 | U13: 7.25 | V13: Scommessa | W13: 1-14 | X13: 6.79 | Y13: infortunato | AA13: sì | AB13: 118054
A14: =IF($AB14="","",IFERROR(INDEX(Giocatori!$A:$A,MATCH($AB14,Giocatori!$AT:$AT,0)),"")) | B14: Pellegrino | D14: Fiorentina | E14: 25 | F14: 0 | G14: 3 | H14: 0.75 | I14: 4 | J14: 2 | K14: 0 | L14: 37 | M14: 9 | N14: 1 | O14: 19 | Q14: Parma | R14: 1 | S14: 2 | T14: 7.62 | U14: 6.73 | V14: Scommessa | W14: 1-14 | X14: 7.35 | AB14: 119848
A15: =IF($AB15="","",IFERROR(INDEX(Giocatori!$A:$A,MATCH($AB15,Giocatori!$AT:$AT,0)),"")) | B15: Berardi | D15: Sassuolo | E15: 32 | F15: 1 | G15: 1 | H15: 0.25 | I15: 3 | J15: 1 | K15: 0 | L15: 26 | M15: 8 | N15: 4 | O15: 12.7 | Q15: Sassuolo | R15: 0 | S15: 1 | T15: 8.17 | U15: 7.1 | V15: Medio | W15: 15-49 | X15: 8.18 | AB15: 35059
A16: =IF($AB16="","",IFERROR(INDEX(Giocatori!$A:$A,MATCH($AB16,Giocatori!$AT:$AT,0)),"")) | B16: Esposito | D16: Inter | E16: 21 | F16: 0 | G16: 4 | H16: 1 | I16: 4 | J16: 2 | K16: 1 | L16: 35 | M16: 7 | N16: 3 | O16: 19 | Q16: Inter | R16: 0 | S16: 0 | T16: 8.75 | U16: 6.86 | V16: Medio | W16: 15-49 | X16: 7.84 | AB16: 118085
A17: =IF($AB17="","",IFERROR(INDEX(Giocatori!$A:$A,MATCH($AB17,Giocatori!$AT:$AT,0)),"")) | B17: Soule | D17: Roma | E17: 23 | F17: 1 | G17: 2 | H17: 0.5 | I17: 4 | J17: 2 | K17: 1 | L17: 33 | M17: 6 | N17: 5 | O17: 19 | Q17: Roma | R17: 0 | S17: 0 | T17: 8.62 | U17: 7 | V17: Semi-top | W17: 50-109 | X17: 8.43 | AB17: 111438
A18: =IF($AB18="","",IFERROR(INDEX(Giocatori!$A:$A,MATCH($AB18,Giocatori!$AT:$AT,0)),"")) | B18: Adams | D18: Torino | E18: 30 | F18: 0 | G18: 2 | H18: 0.5 | I18: 3 | J18: 2 | K18: 0 | L18: 33 | M18: 6 | N18: 2 | O18: 25.3 | Q18: Torino | R18: 0 | S18: 0 | T18: 9 | U18: 6.73 | V18: Scommessa | W18: 1-14 | X18: 7.02 | Y18: infortunato | Z18: 11/10/2026 | AB18: 71896
A19: =IF($AB19="","",IFERROR(INDEX(Giocatori!$A:$A,MATCH($AB19,Giocatori!$AT:$AT,0)),"")) | B19: Bonny | D19: Inter | E19: 23 | F19: 0 | G19: 0 | H19: 0 | I19: 3 | J19: 1 | K19: 0 | L19: 33 | M19: 5 | N19: 4 | O19: 12.7 | Q19: Inter | R19: 0 | S19: 0 | T19: 7.33 | U19: 6.77 | V19: Medio | W19: 15-49 | X19: 7.39 | AB19: 111489
A20: =IF($AB20="","",IFERROR(INDEX(Giocatori!$A:$A,MATCH($AB20,Giocatori!$AT:$AT,0)),"")) | B20: Noslin | D20: Lazio | E20: 27 | F20: 0 | G20: 1 | H20: 0.25 | I20: 3 | J20: 1 | K20: 0 | L20: 29 | M20: 4 | N20: 2 | O20: 12.7 | Q20: Lazio | R20: 0 | S20: 0 | T20: 7 | U20: 6.5 | V20: Scommessa | W20: 1-14 | X20: 6.82 | AB20: 119040
A21: =IF($AB21="","",IFERROR(INDEX(Giocatori!$A:$A,MATCH($AB21,Giocatori!$AT:$AT,0)),""))
A22: =IF($AB22="","",IFERROR(INDEX(Giocatori!$A:$A,MATCH($AB22,Giocatori!$AT:$AT,0)),"")) | B22: SQUADRE MINORI (titolari)
A23: =IF($AB23="","",IFERROR(INDEX(Giocatori!$A:$A,MATCH($AB23,Giocatori!$AT:$AT,0)),"")) | B23: Raimondo | D23: Frosinone | E23: 22 | F23: 1 | G23: 4 | H23: 1 | I23: 4 | J23: 4 | K23: 0 | O23: 38 | R23: 0 | S23: 0 | T23: 9.88 | V23: Top | W23: 110-180 | X23: 10.58 | AB23: 109711
A24: =IF($AB24="","",IFERROR(INDEX(Giocatori!$A:$A,MATCH($AB24,Giocatori!$AT:$AT,0)),"")) | B24: Kvernadze | D24: Frosinone | E24: 23 | F24: 1 | G24: 4 | H24: 1 | I24: 4 | J24: 2 | K24: 1 | O24: 19 | R24: 0 | S24: 0 | T24: 8.75 | V24: Top | W24: 110-180 | X24: 9.45 | AB24: 116477
A25: =IF($AB25="","",IFERROR(INDEX(Giocatori!$A:$A,MATCH($AB25,Giocatori!$AT:$AT,0)),"")) | B25: Gustavo Varela | D25: Monza | E25: 21 | F25: 1 | G25: 3 | H25: 0.75 | I25: 3 | J25: 2 | K25: 0 | O25: 25.3 | R25: 0 | S25: 0 | T25: 8.33 | V25: Semi-top | W25: 50-109 | X25: 9.03 | AB25: 119548
A26: =IF($AB26="","",IFERROR(INDEX(Giocatori!$A:$A,MATCH($AB26,Giocatori!$AT:$AT,0)),"")) | B26: Romero | D26: Parma | E26: 23 | F26: 1 | G26: 1 | H26: 0.25 | I26: 3 | J26: 1 | K26: 0 | O26: 12.7 | R26: 0 | S26: 0 | T26: 7.17 | V26: Medio | W26: 15-49 | X26: 7.87 | AB26: 120550
A27: =IF($AB27="","",IFERROR(INDEX(Giocatori!$A:$A,MATCH($AB27,Giocatori!$AT:$AT,0)),"")) | B27: Mendy | D27: Cagliari | E27: 19 | F27: 1 | G27: 4 | H27: 1 | I27: 4 | J27: 1 | K27: 0 | L27: 9 | M27: 2 | N27: 0 | O27: 9.5 | Q27: Cagliari | R27: 0 | S27: 0 | T27: 7.12 | U27: 6.62 | V27: Medio | W27: 15-49 | X27: 7.61 | AB27: 120334
A28: =IF($AB28="","",IFERROR(INDEX(Giocatori!$A:$A,MATCH($AB28,Giocatori!$AT:$AT,0)),"")) | B28: Bowie | D28: Sassuolo | E28: 24 | F28: 1 | G28: 3 | H28: 0.75 | I28: 4 | J28: 1 | K28: 0 | L28: 14 | M28: 4 | N28: 0 | O28: 9.5 | Q28: Verona | R28: 1 | S28: 0 | T28: 7 | U28: 6.77 | V28: Medio | W28: 15-49 | X28: 7.58 | AB28: 120319
A29: =IF($AB29="","",IFERROR(INDEX(Giocatori!$A:$A,MATCH($AB29,Giocatori!$AT:$AT,0)),"")) | B29: Yeboah | D29: Venezia | E29: 26 | F29: 1 | G29: 3 | H29: 0.75 | I29: 4 | J29: 1 | K29: 0 | O29: 9.5 | R29: 0 | S29: 0 | T29: 6.88 | V29: Medio | W29: 15-49 | X29: 7.58 | AB29: 102086
A30: =IF($AB30="","",IFERROR(INDEX(Giocatori!$A:$A,MATCH($AB30,Giocatori!$AT:$AT,0)),"")) | B30: Lontani | D30: Parma | E30: 18 | F30: 1 | G30: 3 | H30: 0.75 | I30: 4 | J30: 1 | K30: 0 | O30: 9.5 | R30: 0 | S30: 0 | T30: 6.75 | V30: Medio | W30: 15-49 | X30: 7.45 | AB30: 120544
A31: =IF($AB31="","",IFERROR(INDEX(Giocatori!$A:$A,MATCH($AB31,Giocatori!$AT:$AT,0)),"")) | B31: Colombo | D31: Genoa | E31: 24 | F31: 1 | G31: 4 | H31: 1 | I31: 4 | J31: 0 | K31: 1 | L31: 38 | M31: 7 | N31: 1 | O31: 0 | Q31: Genoa | R31: 0 | S31: 1 | T31: 5 | U31: 6.5 | V31: Scommessa | W31: 1-14 | X31: 7.34 | AB31: 95165
A32: =IF($AB32="","",IFERROR(INDEX(Giocatori!$A:$A,MATCH($AB32,Giocatori!$AT:$AT,0)),"")) | B32: Stulic | D32: Lecce | E32: 25 | F32: 1 | G32: 2 | H32: 0.5 | I32: 4 | J32: 0 | K32: 0 | L32: 34 | M32: 4 | N32: 0 | O32: 0 | Q32: Lecce | R32: 0 | S32: 2 | T32: 5.88 | U32: 6.27 | V32: Scommessa | W32: 1-14 | X32: 7.07 | AB32: 97629

Sheet Obiettivi
A1: venduto | B1: nome | C1: soprannome | D1: nome_completo | E1: ruolo | F1: squadra | G1: eta | H1: titolare | I1: da_titolare | J1: pct_titolare | K1: presenze | L1: gol | M1: assist | N1: presenze_prev | O1: gol_prev | P1: assist_prev | Q1: titolare_fonte | R1: obiettivo | S1: fascia | T1: prezzo_indicativo | U1: punteggio | V1: fm | W1: mv | X1: rig_segnati | Y1: fm_prev | Z1: mv_prev | AA1: rig_segnati_prev | AB1: delta_fm | AC1: fm_ponderata | AD1: bonus | AE1: squadra_prev | AF1: cambiato_squadra | AG1: rigorista | AH1: piazzati | AI1: indisponibile | AJ1: infortunio | AK1: rientro_data | AL1: giorni_stop | AM1: stop_lungo | AN1: rientro_nota | AO1: gs_partita_squadra | AP1: gs_partita_squadra_prev | AQ1: rig_parati_prev | AR1: ammonizioni_prev | AS1: espulsioni_prev | AT1: id
A2: =IF($AT2="","",IFERROR(INDEX(Giocatori!$A:$A,MATCH($AT2,Giocatori!$AT:$AT,0)),"")) | B2: Alex Valle | E2: D | F2: Como | G2: 22 | H2: 1 | I2: 3 | J2: 0.75 | K2: 3 | L2: 0 | M2: 1 | N2: 28 | O2: 1 | P2: 4 | Q2: stima da presenze | R2: obiettivo mercato | S2: Semi-top | T2: 15-29 | U2: 7.14 | V2: 6.83 | W2: 6.67 | X2: 0 | Y2: 6.31 | Z2: 6.19 | AA2: 0 | AB2: 0.52 | AC2: 6.44 | AD2: 0.7 | AE2: Como 1907 | AF2: 0 | AG2: 0 | AH2: 0 | AO2: 1 | AP2: 0.76 | AQ2: 0 | AR2: 3 | AS2: 0 | AT2: 115890
A3: =IF($AT3="","",IFERROR(INDEX(Giocatori!$A:$A,MATCH($AT3,Giocatori!$AT:$AT,0)),"")) | B3: Chalobah | E3: D | F3: Como | G3: 27 | H3: 1 | I3: 3 | J3: 0.75 | K3: 3 | L3: 0 | M3: 0 | Q3: stima da presenze | R3: obiettivo mercato | S3: Medio | T3: 5-14 | U3: 7.03 | V3: 6.33 | W3: 6.33 | X3: 0 | AC3: 6.33 | AD3: 0.7 | AF3: 0 | AG3: 0 | AH3: 0 | AO3: 1 | AP3: 0.76 | AT3: 95318
A4: =IF($AT4="","",IFERROR(INDEX(Giocatori!$A:$A,MATCH($AT4,Giocatori!$AT:$AT,0)),"")) | B4: Jacobo Ramon | E4: D | F4: Como | G4: 21 | H4: 1 | I4: 4 | J4: 1 | K4: 4 | L4: 1 | M4: 0 | N4: 32 | O4: 2 | P4: 0 | Q4: stima da presenze | R4: obiettivo mercato | S4: Semi-top | T4: 15-29 | U4: 7.14 | V4: 7.25 | W4: 6.5 | X4: 0 | Y4: 6.14 | Z4: 6.16 | AA4: 0 | AB4: 1.11 | AC4: 6.44 | AD4: 0.7 | AE4: Como 1907 | AF4: 0 | AG4: 0 | AH4: 0 | AO4: 1 | AP4: 0.76 | AQ4: 0 | AR4: 11 | AS4: 1 | AT4: 119152
A5: =IF($AT5="","",IFERROR(INDEX(Giocatori!$A:$A,MATCH($AT5,Giocatori!$AT:$AT,0)),"")) | B5: Yan Couto | E5: D | F5: Como | G5: 24 | H5: 1 | I5: 4 | J5: 1 | K5: 4 | L5: 0 | M5: 1 | Q5: stima da presenze | R5: obiettivo mercato | S5: Semi-top | T5: 15-29 | U5: 7.2 | V5: 6.5 | W5: 6.38 | X5: 0 | AC5: 6.5 | AD5: 0.7 | AF5: 0 | AG5: 0 | AH5: 0 | AO5: 1 | AP5: 0.76 | AT5: 94914
A6: =IF($AT6="","",IFERROR(INDEX(Giocatori!$A:$A,MATCH($AT6,Giocatori!$AT:$AT,0)),"")) | B6: Diouf | E6: C | F6: Inter | G6: 23 | H6: 1 | I6: 3 | J6: 0.75 | K6: 3 | L6: 0 | M6: 3 | N6: 19 | O6: 1 | P6: 0 | Q6: probabili formazioni | R6: obiettivo | S6: Semi-top | T6: 30-59 | U6: 7.75 | V6: 7.67 | W6: 7.17 | X6: 0 | Y6: 6.31 | Z6: 6.08 | AA6: 0 | AB6: 1.36 | AC6: 6.75 | AD6: 1 | AE6: Inter | AF6: 0 | AG6: 0 | AH6: 0 | AO6: 1.5 | AP6: 0.92 | AQ6: 0 | AR6: 1 | AS6: 0 | AT6: 109651
A7: =IF($AT7="","",IFERROR(INDEX(Giocatori!$A:$A,MATCH($AT7,Giocatori!$AT:$AT,0)),"")) | B7: Fagioli | E7: C | F7: Fiorentina | G7: 25 | H7: 1 | I7: 3 | J7: 0.75 | K7: 4 | L7: 0 | M7: 1 | N7: 33 | O7: 2 | P7: 3 | Q7: probabili formazioni | R7: obiettivo | S7: Medio | T7: 10-29 | U7: 7.07 | V7: 6.25 | W7: 6.25 | X7: 0 | Y7: 6.41 | Z7: 6.23 | AA7: 0 | AB7: -0.16 | AC7: 6.37 | AD7: 0.7 | AE7: Fiorentina | AF7: 0 | AG7: 0 | AH7: 0 | AO7: 2.75 | AP7: 1.32 | AQ7: 0 | AR7: 5 | AS7: 0 | AT7: 103752
A8: =IF($AT8="","",IFERROR(INDEX(Giocatori!$A:$A,MATCH($AT8,Giocatori!$AT:$AT,0)),"")) | B8: Ilic | E8: C | F8: Lecce | G8: 25 | H8: 0 | I8: 2 | J8: 0.5 | K8: 3 | L8: 0 | M8: 2 | N8: 8 | O8: 0 | P8: 0 | R8: sesto centrocampista | S8: Scommessa | T8: 1-9 | U8: 6.38 | V8: 6.67 | W8: 6.5 | X8: 0 | Y8: 5.62 | Z8: 5.75 | AA8: 0 | AB8: 1.05 | AC8: 6.18 | AD8: 0.2 | AE8: Torino | AF8: 1 | AG8: 0 | AH8: 0 | AO8: 1.75 | AP8: 1.66 | AQ8: 0 | AR8: 2 | AS8: 0 | AT8: 100764
A9: =IF($AT9="","",IFERROR(INDEX(Giocatori!$A:$A,MATCH($AT9,Giocatori!$AT:$AT,0)),"")) | B9: Mastantuono | E9: C | F9: Fiorentina | G9: 19 | H9: 1 | I9: 4 | J9: 1 | K9: 4 | L9: 3 | M9: 0 | Q9: probabili formazioni | R9: obiettivo | S9: Top | T9: 60-100 | U9: 9.8 | V9: 9 | W9: 6.75 | X9: 0 | AC9: 9 | AD9: 0.8 | AF9: 0 | AG9: 0 | AH9: 1 | AO9: 2.75 | AP9: 1.32 | AT9: 120530
A10: =IF($AT10="","",IFERROR(INDEX(Giocatori!$A:$A,MATCH($AT10,Giocatori!$AT:$AT,0)),"")) | B10: Matic | E10: C | F10: Sassuolo | G10: 38 | H10: 1 | I10: 4 | J10: 1 | K10: 4 | L10: 0 | M10: 1 | N10: 34 | O10: 1 | P10: 1 | Q10: probabili formazioni | R10: obiettivo mercato | S10: Scommessa | T10: 1-9 | U10: 6.31 | V10: 6.25 | W10: 6.25 | X10: 0 | Y10: 6.06 | Z10: 6.07 | AA10: 0 | AB10: 0.19 | AC10: 6.11 | AD10: 0.2 | AE10: Sassuolo | AF10: 0 | AG10: 0 | AH10: 0 | AO10: 1.75 | AP10: 1.32 | AQ10: 0 | AR10: 7 | AS10: 1 | AT10: 19997
A11: =IF($AT11="","",IFERROR(INDEX(Giocatori!$A:$A,MATCH($AT11,Giocatori!$AT:$AT,0)),"")) | B11: Moreira | E11: C | F11: Milan | G11: 22 | H11: 0 | I11: 1 | J11: 0.25 | K11: 2 | L11: 2 | M11: 0 | R11: obiettivo | S11: Top | T11: 60-100 | U11: 10.2 | V11: 10 | W11: 6.75 | X11: 0 | AC11: 10 | AD11: 0.2 | AF11: 0 | AG11: 0 | AH11: 0 | AO11: 1 | AP11: 0.92 | AT11: 113444
A12: =IF($AT12="","",IFERROR(INDEX(Giocatori!$A:$A,MATCH($AT12,Giocatori!$AT:$AT,0)),"")) | B12: Pisilli | E12: C | F12: Roma | G12: 22 | H12: 0 | I12: 1 | J12: 0.25 | K12: 3 | L12: 2 | M12: 0 | N12: 25 | O12: 2 | P12: 4 | R12: obiettivo | S12: Semi-top | T12: 30-59 | U12: 7.93 | V12: 8.67 | W12: 6.83 | X12: 0 | Y12: 6.57 | Z12: 6.28 | AA12: 0 | AB12: 2.1 | AC12: 7.13 | AD12: 0.8 | AE12: Roma | AF12: 0 | AG12: 0 | AH12: 0 | AO12: 0.25 | AP12: 0.82 | AQ12: 0 | AR12: 3 | AS12: 0 | AT12: 116597
A13: =IF($AT13="","",IFERROR(INDEX(Giocatori!$A:$A,MATCH($AT13,Giocatori!$AT:$AT,0)),"")) | B13: Rabiot | E13: C | F13: Milan | G13: 31 | H13: 1 | I13: 2 | J13: 0.5 | K13: 4 | L13: 1 | M13: 2 | N13: 29 | O13: 6 | P13: 4 | Q13: probabili formazioni | R13: obiettivo | S13: Medio | T13: 10-29 | U13: 7.72 | V13: 7.75 | W13: 6.5 | X13: 0 | Y13: 7 | Z13: 6.37 | AA13: 0 | AB13: 0.75 | AC13: 7.22 | AD13: 0.5 | AE13: Milan | AF13: 0 | AG13: 0 | AH13: 0 | AO13: 1 | AP13: 0.92 | AQ13: 0 | AR13: 5 | AS13: 0 | AT13: 38053
A14: =IF($AT14="","",IFERROR(INDEX(Giocatori!$A:$A,MATCH($AT14,Giocatori!$AT:$AT,0)),"")) | B14: Lauriente | D14: Armand Gaëtan Laurienté | E14: A | F14: Sassuolo | G14: 28 | H14: 1 | I14: 4 | J14: 1 | K14: 4 | L14: 0 | M14: 1 | N14: 38 | O14: 7 | P14: 9 | Q14: probabili formazioni | R14: quinta punta | S14: Medio | T14: 15-49 | U14: 7.43 | V14: 6.25 | W14: 6.25 | X14: 0 | Y14: 6.88 | Z14: 6.25 | AA14: 0 | AB14: -0.63 | AC14: 6.73 | AD14: 0.7 | AE14: Sassuolo | AF14: 0 | AG14: 3 | AH14: 2 | AO14: 1.75 | AP14: 1.32 | AQ14: 0 | AR14: 4 | AS14: 0 | AT14: 95435
A15: =IF($AT15="","",IFERROR(INDEX(Giocatori!$A:$A,MATCH($AT15,Giocatori!$AT:$AT,0)),"")) | B15: Malen | D15: Donyell Malen | E15: A | F15: Roma | G15: 27 | H15: 1 | I15: 4 | J15: 1 | K15: 4 | L15: 6 | M15: 0 | N15: 18 | O15: 14 | P15: 2 | Q15: probabili formazioni | R15: obiettivo | S15: Top | T15: 110-180 | U15: 12.07 | V15: 12.5 | W15: 7.38 | X15: 0 | Y15: 9.28 | Z15: 6.75 | AA15: 3 | AB15: 3.22 | AC15: 10.57 | AD15: 1.5 | AE15: Roma | AF15: 0 | AG15: 1 | AH15: 2 | AO15: 0.25 | AP15: 0.82 | AQ15: 0 | AR15: 1 | AS15: 0 | AT15: 63371

Sheet Indisponibili
A1: squadra | B1: nome | C1: ruolo | D1: tipo | E1: infortunio | F1: rientro_data | G1: rientro_nota | H1: fonti
A2: Atalanta | B2: Hien I. | C2: D | D2: infortunato | E2: Problemi alla coscia | F2: 30/09/2026 | G2: il difensore operato a fine giugno per una lesione del tendine prossimale del muscolo semimembranoso della coscia sinistra, in recupero e pronto a tornare in campo dalla metà di ottobre. | H2: fanta.soccer+transfermarkt+fantacalcio.it
